Workbook

Sheet Market Scenario
A1: Scenario | B1: Global_Second | C1: Phase | D1: Phase_Name | E1: Phase_Second | F1: Market_State | G1: Kia | H1: Vintrumite | I1: DB HiTek | J1: POSCO Future M | K1: Hyundai Motor | L1: POSCO Holdings | M1: Samsung Electronics | N1: LS | O1: Samsung SDI | P1: Samsung Electro-Mechanics | Q1: HD Korea Shipbuilding | R1: LS ELECTRIC | S1: Korea Zinc | T1: HMM | U1: Hyundai Mobis | V1: Korea Electric Power | W1: Samsung C&T | X1: SK Inc. | Y1: NAVER | Z1: Kakao | AA1: JUSUNG Engineering | AB1: EO Technics | AC1: Hanmi Semiconductor | AD1: LG Chem | AE1: Shinhan Financial | AF1: LEENO Industrial | AG1: LG Electronics | AH1: Celltrion | AI1: KODEX 200 | AJ1: EcoPro | AK1: Hana Financial | AL1: KODEX Semiconductor | AM1: SK Innovation | AN1: TIGER 200 | AO1: KB Financial | AP1: KODEX Leverage | AQ1: Meritz Financial | AR1: Samsung Biologics | AS1: KODEX KOSDAQ150 | AT1: KODEX KOSDAQ150 Leverage | AU1: Wonik IPS | AV1: EcoPro BM | AW1: KODEX 200 Futures Inverse 2X | AX1: HD Hyundai Electric | AY1: Hyosung Heavy Industries | AZ1: Woori Financial | BA1: HD Hyundai Heavy Industries | BB1: LG Energy Solution | BC1: TIGER Semiconductor TOP10 | BD1: HPSP
A2: Scenario 2 | B2: 1 | C2: 1 | D2: Fake Positive News | E2: 1 | F2: TRADING | G2: 153993.8 | H2: 209016.5 | I2: 161713.9 | J2: 267009.5 | K2: 539016.3 | L2: 501961.6 | M2: 232500 | N2: 509042.5 | O2: 705058.9 | P2: 918054.7 | Q2: 469466.7 | R2: 294029.7 | S2: 1628996 | T2: 21147.56 | U2: 436706.9 | V2: 44495.51 | W2: 319975.9 | X2: 475467.6 | Y2: 1447000 | Z2: 47103.44 | AA2: 126587.7 | AB2: 475017.7 | AC2: 377999.6 | AD2: 428972.6 | AE2: 98006.44 | AF2: 120788.6 | AG2: 143273.2 | AH2: 188381.3 | AI2: 105293.6 | AJ2: 155792.8 | AK2: 126607.4 | AL2: 130460 | AM2: 145712.8 | AN2: 105769.9 | AO2: 157787.8 | AP2: 127790 | AQ2: 113754.6 | AR2: 1484829 | AS2: 20175.32 | AT2: 17085.03 | AU2: 122501.7 | AV2: 215536.6 | AW2: 151.98 | AX2: 1298915 | AY2: 4227657 | AZ2: 33583.59 | BA2: 680032.5 | BB2: 471950.7 | BC2: 42175 | BD2: 54400.9
A3: Scenario 2 | B3: 2 | C3: 1 | D3: Fake Positive News | E3: 2 | F3: TRADING | G3: 154126.4 | H3: 208581.9 | I3: 161772.8 | J3: 267292.9 | K3: 538049.9 | L3: 501379.4 | M3: 232306.4 | N3: 507712.9 | O3: 704847.4 | P3: 920129.7 | Q3: 468291.4 | R3: 293686.4 | S3: 1626007 | T3: 21097.95 | U3: 437003.2 | V3: 44495.7 | W3: 320368.7 | X3: 475586.5 | Y3: 1445214 | Z3: 47060.51 | AA3: 126595 | AB3: 474911 | AC3: 377966.2 | AD3: 428848.4 | AE3: 98160.24 | AF3: 120795.3 | AG3: 143624.6 | AH3: 188689.8 | AI3: 105338.2 | AJ3: 155955.2 | AK3: 126506 | AL3: 130440 | AM3: 145395.7 | AN3: 105873.3 | AO3: 157792 | AP3: 127823.2 | AQ3: 113675.6 | AR3: 1483264 | AS3: 20188.89 | AT3: 17075.25 | AU3: 122372.4 | AV3: 215000 | AW3: 151.79 | AX3: 1299075 | AY3: 4222727 | AZ3: 33643.85 | BA3: 679331.8 | BB3: 471011.7 | BC3: 42187.25 | BD3: 54471.93
A4: Scenario 2 | B4: 3 | C4: 1 | D4: Fake Positive News | E4: 3 | F4: TRADING | G4: 154590.7 | H4: 208027.6 | I4: 161748.2 | J4: 267506.2 | K4: 536731.8 | L4: 500951.5 | M4: 232198.2 | N4: 506562.7 | O4: 704842.4 | P4: 921745.8 | Q4: 467104.2 | R4: 293273.2 | S4: 1623047 | T4: 21042.83 | U4: 437403.9 | V4: 44495.65 | W4: 320693 | X4: 475831.8 | Y4: 1442573 | Z4: 47061.94 | AA4: 126835.5 | AB4: 475294.2 | AC4: 377873 | AD4: 428780.7 | AE4: 98474 | AF4: 120780.8 | AG4: 143866.7 | AH4: 189008.3 | AI4: 105273.2 | AJ4: 156091.7 | AK4: 126571.1 | AL4: 130458.1 | AM4: 145046.9 | AN4: 106020.1 | AO4: 157691.6 | AP4: 127843.4 | AQ4: 113715 | AR4: 1481903 | AS4: 20195.79 | AT4: 17077.34 | AU4: 122304.1 | AV4: 214646.9 | AW4: 151.87 | AX4: 1298334 | AY4: 4219440 | AZ4: 33733.43 | BA4: 679656.3 | BB4: 469769.6 | BC4: 42199.3 | BD4: 54533.93
A5: Scenario 2 | B5: 4 | C5: 1 | D5: Fake Positive News | E5: 4 | F5: TRADING | G5: 154987.5 | H5: 207652.5 | I5: 161786.1 | J5: 267624.3 | K5: 535929.5 | L5: 499675.3 | M5: 232054.4 | N5: 505229.2 | O5: 704816.1 | P5: 923530.1 | Q5: 465933.2 | R5: 293235.9 | S5: 1621320 | T5: 21000.12 | U5: 437853.4 | V5: 44433.93 | W5: 320908.5 | X5: 475912.9 | Y5: 1439709 | Z5: 47057.43 | AA5: 126757.8 | AB5: 475190.6 | AC5: 377866.5 | AD5: 428758.7 | AE5: 98720.37 | AF5: 120812.6 | AG5: 144138 | AH5: 189280 | AI5: 105337.6 | AJ5: 156325.9 | AK5: 126479.6 | AL5: 130466.8 | AM5: 144747.9 | AN5: 106051.9 | AO5: 157652 | AP5: 127833.5 | AQ5: 113744.4 | AR5: 1479954 | AS5: 20211.21 | AT5: 17053.83 | AU5: 122293.4 | AV5: 214320.3 | AW5: 151.94 | AX5: 1297102 | AY5: 4213606 | AZ5: 33803.91 | BA5: 679177.9 | BB5: 468852.2 | BC5: 42209.99 | BD5: 54564.59
A6: Scenario 2 | B6: 5 | C6: 1 | D6: Fake Positive News | E6: 5 | F6: TRADING | G6: 155043.9 | H6: 207299 | I6: 161843.4 | J6: 267527.7 | K6: 534831.5 | L6: 498657.9 | M6: 231711.5 | N6: 503825.8 | O6: 704721.2 | P6: 926458.5 | Q6: 464584 | R6: 292865.8 | S6: 1618992 | T6: 20942.91 | U6: 438436.7 | V6: 44391.57 | W6: 321350.6 | X6: 475844.3 | Y6: 1436938 | Z6: 47056.68 | AA6: 126847.7 | AB6: 474843.6 | AC6: 377951.6 | AD6: 428496.5 | AE6: 98831.17 | AF6: 120824.8 | AG6: 144498.7 | AH6: 189484.4 | AI6: 105333.1 | AJ6: 156519.7 | AK6: 126279.6 | AL6: 130472.3 | AM6: 144465.6 | AN6: 105946.8 | AO6: 157621.3 | AP6: 127828.4 | AQ6: 113724.7 | AR6: 1479084 | AS6: 20206.76 | AT6: 17039.37 | AU6: 122146.5 | AV6: 213811.4 | AW6: 152.13 | AX6: 1293458 | AY6: 4211795 | AZ6: 33871.96 | BA6: 678866.6 | BB6: 468316.8 | BC6: 42209.47 | BD6: 54616.51
A7: Scenario 2 | B7: 6 | C7: 1 | D7: Fake Positive News | E7: 6 | F7: TRADING | G7: 155419.6 | H7: 206847.2 | I7: 161858.2 | J7: 267724.5 | K7: 533669.4 | L7: 497906.1 | M7: 231474.6 | N7: 502275.8 | O7: 705022.6 | P7: 929435 | Q7: 463316.3 | R7: 292825.5 | S7: 1614799 | T7: 20894.15 | U7: 439061 | V7: 44394.39 | W7: 321909.2 | X7: 475992.3 | Y7: 1434924 | Z7: 47045.98 | AA7: 126870.9 | AB7: 474551.8 | AC7: 377881.2 | AD7: 428240.6 | AE7: 99015.68 | AF7: 120803.2 | AG7: 144825.8 | AH7: 189960.9 | AI7: 105345.5 | AJ7: 156740.1 | AK7: 126246.1 | AL7: 130490 | AM7: 144205.7 | AN7: 106127.9 | AO7: 157685.8 | AP7: 127814.6 | AQ7: 113679.8 | AR7: 1479227 | AS7: 20198.38 | AT7: 17014.47 | AU7: 122115.8 | AV7: 213349.7 | AW7: 152.33 | AX7: 1291950 | AY7: 4206536 | AZ7: 33948.4 | BA7: 678640.5 | BB7: 467508.9 | BC7: 42204.72 | BD7: 54630.25
A8: Scenario 2 | B8: 7 | C8: 1 | D8: Fake Positive News | E8: 7 | F8: TRADING | G8: 155753 | H8: 206385.1 | I8: 161879.8 | J8: 267966.8 | K8: 532377.7 | L8: 497054.4 | M8: 231145.2 | N8: 500742.5 | O8: 705080.7 | P8: 932335.4 | Q8: 462079.5 | R8: 292717 | S8: 1612451 | T8: 20845.85 | U8: 439682.6 | V8: 44361.89 | W8: 322313.1 | X8: 476260.3 | Y8: 1433236 | Z8: 47047.67 | AA8: 126800.9 | AB8: 474461.8 | AC8: 377949.1 | AD8: 428184.8 | AE8: 99336.81 | AF8: 120778.8 | AG8: 145202.5 | AH8: 190116.1 | AI8: 105344.7 | AJ8: 157011.7 | AK8: 126078.3 | AL8: 130477.8 | AM8: 143982.2 | AN8: 106220.5 | AO8: 157614.5 | AP8: 127786.5 | AQ8: 113694.8 | AR8: 1478673 | AS8: 20188.06 | AT8: 16997.95 | AU8: 122059.2 | AV8: 212823.6 | AW8: 152.43 | AX8: 1291310 | AY8: 4204625 | AZ8: 34025.81 | BA8: 678880.4 | BB8: 466533.5 | BC8: 42202.33 | BD8: 54735.29
A9: Scenario 2 | B9: 8 | C9: 1 | D9: Fake Positive News | E9: 8 | F9: TRADING | G9: 155973.8 | H9: 205966.6 | I9: 161866.7 | J9: 268446.2 | K9: 530870.6 | L9: 496132.7 | M9: 230946.5 | N9: 499513.3 | O9: 705077.8 | P9: 935333.5 | Q9: 460350.7 | R9: 292066.9 | S9: 1609257 | T9: 20796.36 | U9: 440267.7 | V9: 44329.66 | W9: 322775.8 | X9: 476714.4 | Y9: 1432722 | Z9: 47054.67 | AA9: 126993.6 | AB9: 474479.1 | AC9: 378019.8 | AD9: 428358 | AE9: 99331.23 | AF9: 120754.1 | AG9: 145534 | AH9: 190211.7 | AI9: 105323.4 | AJ9: 157264.4 | AK9: 126088.5 | AL9: 130464.3 | AM9: 143741.3 | AN9: 106227.7 | AO9: 157638.7 | AP9: 127777.3 | AQ9: 113705 | AR9: 1477031 | AS9: 20185.55 | AT9: 16978.82 | AU9: 122083.5 | AV9: 212369.8 | AW9: 152.31 | AX9: 1291762 | AY9: 4199523 | AZ9: 34109.19 | BA9: 679479.7 | BB9: 465548.2 | BC9: 42207.89 | BD9: 54775.96
A10: Scenario 2 | B10: 9 | C10: 1 | D10: Fake Positive News | E10: 9 | F10: TRADING | G10: 156214.3 | H10: 205448.4 | I10: 161970 | J10: 268740.2 | K10: 529315.9 | L10: 495388.3 | M10: 230735.2 | N10: 498121.6 | O10: 705297.7 | P10: 937582.3 | Q10: 459249.4 | R10: 291838.2 | S10: 1605750 | T10: 20740.96 | U10: 440969 | V10: 44314.2 | W10: 323031.4 | X10: 477534.7 | Y10: 1430229 | Z10: 47046.33 | AA10: 127166.6 | AB10: 474397.7 | AC10: 377936.8 | AD10: 428454.5 | AE10: 99432.6 | AF10: 120742.7 | AG10: 145854.8 | AH10: 190275 | AI10: 105345.6 | AJ10: 157496.8 | AK10: 126109.3 | AL10: 130457.9 | AM10: 143438.6 | AN10: 106337.6 | AO10: 157563.3 | AP10: 127790.6 | AQ10: 113699 | AR10: 1473124 | AS10: 20179.73 | AT10: 16961.76 | AU10: 122067.6 | AV10: 211621.6 | AW10: 152.31 | AX10: 1292229 | AY10: 4194095 | AZ10: 34201.89 | BA10: 679646.1 | BB10: 464604.2 | BC10: 42202.24 | BD10: 54803.87
A11: Scenario 2 | B11: 10 | C11: 1 | D11: Fake Positive News | E11: 10 | F11: TRADING | G11: 156557.5 | H11: 204851.5 | I11: 162058.4 | J11: 268692.2 | K11: 528122.3 | L11: 494509.8 | M11: 230418.2 | N11: 496384 | O11: 705234.7 | P11: 938986.3 | Q11: 457933.3 | R11: 291617.5 | S11: 1602240 | T11: 20691.8 | U11: 441451.6 | V11: 44289.63 | W11: 323511.8 | X11: 477825.7 | Y11: 1428324 | Z11: 47098.82 | AA11: 127281.4 | AB11: 474486.9 | AC11: 377978.4 | AD11: 428592.4 | AE11: 99587.64 | AF11: 120713.2 | AG11: 146235.9 | AH11: 190517.7 | AI11: 105268.4 | AJ11: 157691.1 | AK11: 125884.5 | AL11: 130447.5 | AM11: 143172 | AN11: 106481.3 | AO11: 157512.9 | AP11: 127800.2 | AQ11: 113717.4 | AR11: 1472793 | AS11: 20191.5 | AT11: 16932.6 | AU11: 122052.8 | AV11: 211161.4 | AW11: 152.57 | AX11: 1289572 | AY11: 4194194 | AZ11: 34277.26 | BA11: 679657.2 | BB11: 463580.7 | BC11: 42199.93 | BD11: 54820.06
A12: Scenario 2 | B12: 11 | C12: 1 | D12: Fake Positive News | E12: 11 | F12: TRADING | G12: 156739.6 | H12: 204254.2 | I12: 161947.3 | J12: 268962.8 | K12: 527040.7 | L12: 493418 | M12: 230286.3 | N12: 495106.1 | O12: 705440 | P12: 940656.1 | Q12: 456804.7 | R12: 291374.4 | S12: 1599391 | T12: 20642.49 | U12: 442107.7 | V12: 44251.07 | W12: 324096 | X12: 478290.9 | Y12: 1425856 | Z12: 47060.5 | AA12: 127392 | AB12: 474044.1 | AC12: 378061.6 | AD12: 428584.9 | AE12: 99603.12 | AF12: 120726.9 | AG12: 146495.5 | AH12: 190747.9 | AI12: 105273.1 | AJ12: 158005.3 | AK12: 125741.1 | AL12: 130458.1 | AM12: 142939.4 | AN12: 106557.9 | AO12: 157502.3 | AP12: 127830.1 | AQ12: 113717 | AR12: 1468694 | AS12: 20193.07 | AT12: 16926.12 | AU12: 122058.3 | AV12: 210712.7 | AW12: 152.67 | AX12: 1288231 | AY12: 4193903 | AZ12: 34339.49 | BA12: 679302.4 | BB12: 462646 | BC12: 42206.71 | BD12: 54878.88
A13: Scenario 2 | B13: 12 | C13: 1 | D13: Fake Positive News | E13: 12 | F13: TRADING | G13: 156938 | H13: 203889.2 | I13: 161998.2 | J13: 269018.9 | K13: 525748.6 | L13: 492561.7 | M13: 230032.1 | N13: 494223.8 | O13: 705252.6 | P13: 942174.2 | Q13: 455340.9 | R13: 291103.6 | S13: 1598340 | T13: 20591.33 | U13: 442009.8 | V13: 44221.13 | W13: 324584.8 | X13: 478111.2 | Y13: 1425756 | Z13: 47074.22 | AA13: 127790.5 | AB13: 473813.9 | AC13: 377921.6 | AD13: 428339.4 | AE13: 99854.5 | AF13: 120729.6 | AG13: 146705.6 | AH13: 190966.7 | AI13: 105221 | AJ13: 158278.3 | AK13: 125652.1 | AL13: 130450.8 | AM13: 142644.8 | AN13: 106542.5 | AO13: 157513.3 | AP13: 127815 | AQ13: 113672.2 | AR13: 1466055 | AS13: 20176.38 | AT13: 16897.36 | AU13: 121852.6 | AV13: 210179.2 | AW13: 152.75 | AX13: 1285993 | AY13: 4189794 | AZ13: 34411.96 | BA13: 678893.4 | BB13: 461817 | BC13: 42198.9 | BD13: 54913.82
... A1801: Scenario 2 | B1801: 1800 | C1801: 6 | D1801: Negative Shock | E1801: 300 | F1801: TRADING | G1801: 105759.4 | H1801: 302259.4 | I1801: 122800 | J1801: 204571.3 | K1801: 723917.2 | L1801: 733837.3 | M1801: 147977.8 | N1801: 380166.8 | O1801: 501560.1 | P1801: 660110 | Q1801: 376852.8 | R1801: 246525.7 | S1801: 2158090 | T1801: 31174.23 | U1801: 312827.2 | V1801: 46467.81 | W1801: 233962.8 | X1801: 372180.5 | Y1801: 952354 | Z1801: 35787.24 | AA1801: 83154.61 | AB1801: 375942.1 | AC1801: 242300.5 | AD1801: 305477.8 | AE1801: 63816.15 | AF1801: 102131.3 | AG1801: 122591.9 | AH1801: 136144.9 | AI1801: 71790.33 | AJ1801: 128659.7 | AK1801: 104900.1 | AL1801: 96262.03 | AM1801: 121003.6 | AN1801: 73478.68 | AO1801: 127808.6 | AP1801: 105568.4 | AQ1801: 84255.97 | AR1801: 911972.3 | AS1801: 12715.97 | AT1801: 12576.68 | AU1801: 98865.03 | AV1801: 264047.5 | AW1801: 154.0335 | AX1801: 932366.6 | AY1801: 3148761 | AZ1801: 29993.67 | BA1801: 517074.7 | BB1801: 645330.4 | BC1801: 32475.35 | BD1801: 37121.09

Sheet Data Audit
A1: Scenario | B1: Global_Second | C1: Phase | D1: Phase_Name | E1: Phase_Second | F1: Market_State | G1: Kia | H1: Kia Δ% | I1: Vintrumite | J1: Vintrumite Δ% | K1: DB HiTek | L1: DB HiTek Δ% | M1: POSCO Future M | N1: POSCO Future M Δ% | O1: Hyundai Motor | P1: Hyundai Motor Δ% | Q1: POSCO Holdings | R1: POSCO Holdings Δ% | S1: Samsung Electronics | T1: Samsung Electronics Δ% | U1: LS | V1: LS Δ% | W1: Samsung SDI | X1: Samsung SDI Δ% | Y1: Samsung Electro-Mechanics | Z1: Samsung Electro-Mechanics Δ% | AA1: HD Korea Shipbuilding | AB1: HD Korea Shipbuilding Δ% | AC1: LS ELECTRIC | AD1: LS ELECTRIC Δ% | AE1: Korea Zinc | AF1: Korea Zinc Δ% | AG1: HMM | AH1: HMM Δ% | AI1: Hyundai Mobis | AJ1: Hyundai Mobis Δ% | AK1: Korea Electric Power | AL1: Korea Electric Power Δ% | AM1: Samsung C&T | AN1: Samsung C&T Δ% | AO1: SK Inc. | AP1: SK Inc. Δ% | AQ1: NAVER | AR1: NAVER Δ% | AS1: Kakao | AT1: Kakao Δ% | AU1: JUSUNG Engineering | AV1: JUSUNG Engineering Δ% | AW1: EO Technics | AX1: EO Technics Δ% | AY1: Hanmi Semiconductor | AZ1: Hanmi Semiconductor Δ% | BA1: LG Chem | BB1: LG Chem Δ% | BC1: Shinhan Financial | BD1: Shinhan Financial Δ% | BE1: LEENO Industrial | BF1: LEENO Industrial Δ% | BG1: LG Electronics | BH1: LG Electronics Δ% | BI1: Celltrion | BJ1: Celltrion Δ% | BK1: KODEX 200 | BL1: KODEX 200 Δ% | BM1: EcoPro | BN1: EcoPro Δ% | BO1: Hana Financial | BP1: Hana Financial Δ% | BQ1: KODEX Semiconductor | BR1: KODEX Semiconductor Δ% | BS1: SK Innovation | BT1: SK Innovation Δ% | BU1: TIGER 200 | BV1: TIGER 200 Δ% | BW1: KB Financial | BX1: KB Financial Δ% | BY1: KODEX Leverage | BZ1: KODEX Leverage Δ% | CA1: Meritz Financial | CB1: Meritz Financial Δ% | CC1: Samsung Biologics | CD1: Samsung Biologics Δ% | CE1: KODEX KOSDAQ150 | CF1: KODEX KOSDAQ150 Δ% | CG1: KODEX KOSDAQ150 Leverage | CH1: KODEX KOSDAQ150 Leverage Δ% | CI1: Wonik IPS | CJ1: Wonik IPS Δ% | CK1: EcoPro BM | CL1: EcoPro BM Δ% | CM1: KODEX 200 Futures Inverse 2X | CN1: KODEX 200 Futures Inverse 2X Δ% | CO1: HD Hyundai Electric | CP1: HD Hyundai Electric Δ% | CQ1: Hyosung Heavy Industries | CR1: Hyosung Heavy Industries Δ% | CS1: Woori Financial | CT1: Woori Financial Δ% | CU1: HD Hyundai Heavy Industries | CV1: HD Hyundai Heavy Industries Δ% | CW1: LG Energy Solution | CX1: LG Energy Solution Δ% | CY1: TIGER Semiconductor TOP10 | CZ1: TIGER Semiconductor TOP10 Δ% | DA1: HPSP | DB1: HPSP Δ% | DD1: ±30% PRICE-LIMIT AUDIT
A2: ='Market Scenario'!A2 -> Scenario 2 | B2: ='Market Scenario'!B2 -> 1 | C2: ='Market Scenario'!C2 -> 1 | D2: ='Market Scenario'!D2 -> Fake Positive News | E2: ='Market Scenario'!E2 -> 1 | F2: ='Market Scenario'!F2 -> TRADING | G2: ='Market Scenario'!G2 -> 153993.8 | H2: =IFERROR('Market Scenario'!G2/'Market Scenario'!G$2-1,"") -> 0 | I2: ='Market Scenario'!H2 -> 209016.5 | J2: =IFERROR('Market Scenario'!H2/'Market Scenario'!H$2-1,"") -> 0 | K2: ='Market Scenario'!I2 -> 161713.9 | L2: =IFERROR('Market Scenario'!I2/'Market Scenario'!I$2-1,"") -> 0 | M2: ='Market Scenario'!J2 -> 267009.5 | N2: =IFERROR('Market Scenario'!J2/'Market Scenario'!J$2-1,"") -> 0 | O2: ='Market Scenario'!K2 -> 539016.3 | P2: =IFERROR('Market Scenario'!K2/'Market Scenario'!K$2-1,"") -> 0 | Q2: ='Market Scenario'!L2 -> 501961.6 | R2: =IFERROR('Market Scenario'!L2/'Market Scenario'!L$2-1,"") -> 0 | S2: ='Market Scenario'!M2 -> 232500 | T2: =IFERROR('Market Scenario'!M2/'Market Scenario'!M$2-1,"") -> 0 | U2: ='Market Scenario'!N2 -> 509042.5 | V2: =IFERROR('Market Scenario'!N2/'Market Scenario'!N$2-1,"") -> 0 | W2: ='Market Scenario'!O2 -> 705058.9 | X2: =IFERROR('Market Scenario'!O2/'Market Scenario'!O$2-1,"") -> 0 | Y2: ='Market Scenario'!P2 -> 918054.7 | Z2: =IFERROR('Market Scenario'!P2/'Market Scenario'!P$2-1,"") -> 0 | AA2: ='Market Scenario'!Q2 -> 469466.7 | AB2: =IFERROR('Market Scenario'!Q2/'Market Scenario'!Q$2-1,"") -> 0 | AC2: ='Market Scenario'!R2 -> 294029.7 | AD2: =IFERROR('Market Scenario'!R2/'Market Scenario'!R$2-1,"") -> 0 | AE2: ='Market Scenario'!S2 -> 1628996 | AF2: =IFERROR('Market Scenario'!S2/'Market Scenario'!S$2-1,"") -> 0 | AG2: ='Market Scenario'!T2 -> 21147.56 | AH2: =IFERROR('Market Scenario'!T2/'Market Scenario'!T$2-1,"") -> 0 | AI2: ='Market Scenario'!U2 -> 436706.9 | AJ2: =IFERROR('Market Scenario'!U2/'Market Scenario'!U$2-1,"") -> 0 | AK2: ='Market Scenario'!V2 -> 44495.51 | AL2: =IFERROR('Market Scenario'!V2/'Market Scenario'!V$2-1,"") -> 0 | AM2: ='Market Scenario'!W2 -> 319975.9 | AN2: =IFERROR('Market Scenario'!W2/'Market Scenario'!W$2-1,"") -> 0 | AO2: ='Market Scenario'!X2 -> 475467.6 | AP2: =IFERROR('Market Scenario'!X2/'Market Scenario'!X$2-1,"") -> 0 | AQ2: ='Market Scenario'!Y2 -> 1447000 | AR2: =IFERROR('Market Scenario'!Y2/'Market Scenario'!Y$2-1,"") -> 0 | AS2: ='Market Scenario'!Z2 -> 47103.44 | AT2: =IFERROR('Market Scenario'!Z2/'Market Scenario'!Z$2-1,"") -> 0 | AU2: ='Market Scenario'!AA2 -> 126587.7 | AV2: =IFERROR('Market Scenario'!AA2/'Market Scenario'!AA$2-1,"") -> 0 | AW2: ='Market Scenario'!AB2 -> 475017.7 | AX2: =IFERROR('Market Scenario'!AB2/'Market Scenario'!AB$2-1,"") -> 0 | AY2: ='Market Scenario'!AC2 -> 377999.6 | AZ2: =IFERROR('Market Scenario'!AC2/'Market Scenario'!AC$2-1,"") -> 0 | BA2: ='Market Scenario'!AD2 -> 428972.6 | BB2: =IFERROR('Market Scenario'!AD2/'Market Scenario'!AD$2-1,"") -> 0 | BC2: ='Market Scenario'!AE2 -> 98006.44 | BD2: =IFERROR('Market Scenario'!AE2/'Market Scenario'!AE$2-1,"") -> 0 | BE2: ='Market Scenario'!AF2 -> 120788.6 | BF2: =IFERROR('Market Scenario'!AF2/'Market Scenario'!AF$2-1,"") -> 0 | BG2: ='Market Scenario'!AG2 -> 143273.2 | BH2: =IFERROR('Market Scenario'!AG2/'Market Scenario'!AG$2-1,"") -> 0 | BI2: ='Market Scenario'!AH2 -> 188381.3 | BJ2: =IFERROR('Market Scenario'!AH2/'Market Scenario'!AH$2-1,"") -> 0 | BK2: ='Market Scenario'!AI2 -> 105293.6 | BL2: =IFERROR('Market Scenario'!AI2/'Market Scenario'!AI$2-1,"") -> 0 | BM2: ='Market Scenario'!AJ2 -> 155792.8 | BN2: =IFERROR('Market Scenario'!AJ2/'Market Scenario'!AJ$2-1,"") -> 0 | BO2: ='Market Scenario'!AK2 -> 126607.4 | BP2: =IFERROR('Market Scenario'!AK2/'Market Scenario'!AK$2-1,"") -> 0 | BQ2: ='Market Scenario'!AL2 -> 130460 | BR2: =IFERROR('Market Scenario'!AL2/'Market Scenario'!AL$2-1,"") -> 0 | BS2: ='Market Scenario'!AM2 -> 145712.8 | BT2: =IFERROR('Market Scenario'!AM2/'Market Scenario'!AM$2-1,"") -> 0 | BU2: ='Market Scenario'!AN2 -> 105769.9 | BV2: =IFERROR('Market Scenario'!AN2/'Market Scenario'!AN$2-1,"") -> 0 | BW2: ='Market Scenario'!AO2 -> 157787.8 | BX2: =IFERROR('Market Scenario'!AO2/'Market Scenario'!AO$2-1,"") -> 0 | BY2: ='Market Scenario'!AP2 -> 127790 | BZ2: =IFERROR('Market Scenario'!AP2/'Market Scenario'!AP$2-1,"") -> 0 | CA2: ='Market Scenario'!AQ2 -> 113754.6 | CB2: =IFERROR('Market Scenario'!AQ2/'Market Scenario'!AQ$2-1,"") -> 0 | CC2: ='Market Scenario'!AR2 -> 1484829 | CD2: =IFERROR('Market Scenario'!AR2/'Market Scenario'!AR$2-1,"") -> 0 | CE2: ='Market Scenario'!AS2 -> 20175.32 | CF2: =IFERROR('Market Scenario'!AS2/'Market Scenario'!AS$2-1,"") -> 0 | CG2: ='Market Scenario'!AT2 -> 17085.03 | CH2: =IFERROR('Market Scenario'!AT2/'Market Scenario'!AT$2-1,"") -> 0 | CI2: ='Market Scenario'!AU2 -> 122501.7 | CJ2: =IFERROR('Market Scenario'!AU2/'Market Scenario'!AU$2-1,"") -> 0 | CK2: ='Market Scenario'!AV2 -> 215536.6 | CL2: =IFERROR('Market Scenario'!AV2/'Market Scenario'!AV$2-1,"") -> 0 | CM2: ='Market Scenario'!AW2 -> 151.98 | CN2: =IFERROR('Market Scenario'!AW2/'Market Scenario'!AW$2-1,"") -> 0 | CO2: ='Market Scenario'!AX2 -> 1298915 | CP2: =IFERROR('Market Scenario'!AX2/'Market Scenario'!AX$2-1,"") -> 0 | CQ2: ='Market Scenario'!AY2 -> 4227657 | CR2: =IFERROR('Market Scenario'!AY2/'Market Scenario'!AY$2-1,"") -> 0 | CS2: ='Market Scenario'!AZ2 -> 33583.59 | CT2: =IFERROR('Market Scenario'!AZ2/'Market Scenario'!AZ$2-1,"") -> 0 | CU2: ='Market Scenario'!BA2 -> 680032.5 | CV2: =IFERROR('Market Scenario'!BA2/'Market Scenario'!BA$2-1,"") -> 0 | CW2: ='Market Scenario'!BB2 -> 471950.7 | CX2: =IFERROR('Market Scenario'!BB2/'Market Scenario'!BB$2-1,"") -> 0 | CY2: ='Market Scenario'!BC2 -> 42175 | CZ2: =IFERROR('Market Scenario'!BC2/'Market Scenario'!BC$2-1,"") -> 0 | DA2: ='Market Scenario'!BD2 -> 54400.9 | DB2: =IFERROR('Market Scenario'!BD2/'Market Scenario'!BD$2-1,"") -> 0 | DD2: HOW TO USE • Each ticker has Price + Δ% vs the beginning of the AM/PM session. • AM = Phase_Second 1–150; PM = 151–300. • Any move above +30% or below -30% is highlighted RED. • You can paste/replace Tab 1 later, provided the same 56-column structure and ticker order are kept.
A3: ='Market Scenario'!A3 -> Scenario 2 | B3: ='Market Scenario'!B3 -> 2 | C3: ='Market Scenario'!C3 -> 1 | D3: ='Market Scenario'!D3 -> Fake Positive News | E3: ='Market Scenario'!E3 -> 2 | F3: ='Market Scenario'!F3 -> TRADING | G3: ='Market Scenario'!G3 -> 154126.4 | H3: =IFERROR('Market Scenario'!G3/'Market Scenario'!G$2-1,"") -> 0.00086107363 | I3: ='Market Scenario'!H3 -> 208581.9 | J3: =IFERROR('Market Scenario'!H3/'Market Scenario'!H$2-1,"") -> -0.0020792617 | K3: ='Market Scenario'!I3 -> 161772.8 | L3: =IFERROR('Market Scenario'!I3/'Market Scenario'!I$2-1,"") -> 0.00036422348 | M3: ='Market Scenario'!J3 -> 267292.9 | N3: =IFERROR('Market Scenario'!J3/'Market Scenario'!J$2-1,"") -> 0.0010613855 | O3: ='Market Scenario'!K3 -> 538049.9 | P3: =IFERROR('Market Scenario'!K3/'Market Scenario'!K$2-1,"") -> -0.0017928957 | Q3: ='Market Scenario'!L3 -> 501379.4 | R3: =IFERROR('Market Scenario'!L3/'Market Scenario'!L$2-1,"") -> -0.0011598497 | S3: ='Market Scenario'!M3 -> 232306.4 | T3: =IFERROR('Market Scenario'!M3/'Market Scenario'!M$2-1,"") -> -0.00083268817 | U3: ='Market Scenario'!N3 -> 507712.9 | V3: =IFERROR('Market Scenario'!N3/'Market Scenario'!N$2-1,"") -> -0.0026119627 | W3: ='Market Scenario'!O3 -> 704847.4 | X3: =IFERROR('Market Scenario'!O3/'Market Scenario'!O$2-1,"") -> -0.00029997494 | Y3: ='Market Scenario'!P3 -> 920129.7 | Z3: =IFERROR('Market Scenario'!P3/'Market Scenario'!P$2-1,"") -> 0.0022602139 | AA3: ='Market Scenario'!Q3 -> 468291.4 | AB3: =IFERROR('Market Scenario'!Q3/'Market Scenario'!Q$2-1,"") -> -0.0025034789 | AC3: ='Market Scenario'!R3 -> 293686.4 | AD3: =IFERROR('Market Scenario'!R3/'Market Scenario'!R$2-1,"") -> -0.0011675691 | AE3: ='Market Scenario'!S3 -> 1626007 | AF3: =IFERROR('Market Scenario'!S3/'Market Scenario'!S$2-1,"") -> -0.0018348725 | AG3: ='Market Scenario'!T3 -> 21097.95 | AH3: =IFERROR('Market Scenario'!T3/'Market Scenario'!T$2-1,"") -> -0.0023458971 | AI3: ='Market Scenario'!U3 -> 437003.2 | AJ3: =IFERROR('Market Scenario'!U3/'Market Scenario'!U$2-1,"") -> 0.0006784871 | AK3: ='Market Scenario'!V3 -> 44495.7 | AL3: =IFERROR('Market Scenario'!V3/'Market Scenario'!V$2-1,"") -> 4.2700938e-06 | AM3: ='Market Scenario'!W3 -> 320368.7 | AN3: =IFERROR('Market Scenario'!W3/'Market Scenario'!W$2-1,"") -> 0.0012275925 | AO3: ='Market Scenario'!X3 -> 475586.5 | AP3: =IFERROR('Market Scenario'!X3/'Market Scenario'!X$2-1,"") -> 0.00025006962 | AQ3: ='Market Scenario'!Y3 -> 1445214 | AR3: =IFERROR('Market Scenario'!Y3/'Market Scenario'!Y$2-1,"") -> -0.0012342778 | AS3: ='Market Scenario'!Z3 -> 47060.51 | AT3: =IFERROR('Market Scenario'!Z3/'Market Scenario'!Z$2-1,"") -> -0.0009113984 | AU3: ='Market Scenario'!AA3 -> 126595 | AV3: =IFERROR('Market Scenario'!AA3/'Market Scenario'!AA$2-1,"") -> 5.766753e-05 | AW3: ='Market Scenario'!AB3 -> 474911 | AX3: =IFERROR('Market Scenario'!AB3/'Market Scenario'!AB$2-1,"") -> -0.00022462321 | AY3: ='Market Scenario'!AC3 -> 377966.2 | AZ3: =IFERROR('Market Scenario'!AC3/'Market Scenario'!AC$2-1,"") -> -8.8359882e-05 | BA3: ='Market Scenario'!AD3 -> 428848.4 | BB3: =IFERROR('Market Scenario'!AD3/'Market Scenario'!AD$2-1,"") -> -0.00028952898 | BC3: ='Market Scenario'!AE3 -> 98160.24 | BD3: =IFERROR('Market Scenario'!AE3/'Market Scenario'!AE$2-1,"") -> 0.0015692846 | BE3: ='Market Scenario'!AF3 -> 120795.3 | BF3: =IFERROR('Market Scenario'!AF3/'Market Scenario'!AF$2-1,"") -> 5.5468811e-05 | BG3: ='Market Scenario'!AG3 -> 143624.6 | BH3: =IFERROR('Market Scenario'!AG3/'Market Scenario'!AG$2-1,"") -> 0.0024526569 | BI3: ='Market Scenario'!AH3 -> 188689.8 | BJ3: =IFERROR('Market Scenario'!AH3/'Market Scenario'!AH$2-1,"") -> 0.001637636 | BK3: ='Market Scenario'!AI3 -> 105338.2 | BL3: =IFERROR('Market Scenario'!AI3/'Market Scenario'!AI$2-1,"") -> 0.0004235775 | BM3: ='Market Scenario'!AJ3 -> 155955.2 | BN3: =IFERROR('Market Scenario'!AJ3/'Market Scenario'!AJ$2-1,"") -> 0.0010424102 | BO3: ='Market Scenario'!AK3 -> 126506 | BP3: =IFERROR('Market Scenario'!AK3/'Market Scenario'!AK$2-1,"") -> -0.00080090105 | BQ3: ='Market Scenario'!AL3 -> 130440 | BR3: =IFERROR('Market Scenario'!AL3/'Market Scenario'!AL$2-1,"") -> -0.00015330369 | BS3: ='Market Scenario'!AM3 -> 145395.7 | BT3: =IFERROR('Market Scenario'!AM3/'Market Scenario'!AM$2-1,"") -> -0.0021761987 | BU3: ='Market Scenario'!AN3 -> 105873.3 | BV3: =IFERROR('Market Scenario'!AN3/'Market Scenario'!AN$2-1,"") -> 0.00097759381 | BW3: ='Market Scenario'!AO3 -> 157792 | BX3: =IFERROR('Market Scenario'!AO3/'Market Scenario'!AO$2-1,"") -> 2.6618028e-05 | BY3: ='Market Scenario'!AP3 -> 127823.2 | BZ3: =IFERROR('Market Scenario'!AP3/'Market Scenario'!AP$2-1,"") -> 0.00025980124 | CA3: ='Market Scenario'!AQ3 -> 113675.6 | CB3: =IFERROR('Market Scenario'!AQ3/'Market Scenario'!AQ$2-1,"") -> -0.00069447741 | CC3: ='Market Scenario'!AR3 -> 1483264 | CD3: =IFERROR('Market Scenario'!AR3/'Market Scenario'!AR$2-1,"") -> -0.0010539934 | CE3: ='Market Scenario'!AS3 -> 20188.89 | CF3: =IFERROR('Market Scenario'!AS3/'Market Scenario'!AS$2-1,"") -> 0.00067260395 | CG3: ='Market Scenario'!AT3 -> 17075.25 | CH3: =IFERROR('Market Scenario'!AT3/'Market Scenario'!AT$2-1,"") -> -0.00057243095 | CI3: ='Market Scenario'!AU3 -> 122372.4 | CJ3: =IFERROR('Market Scenario'!AU3/'Market Scenario'!AU$2-1,"") -> -0.0010554956 | CK3: ='Market Scenario'!AV3 -> 215000 | CL3: =IFERROR('Market Scenario'!AV3/'Market Scenario'!AV$2-1,"") -> -0.0024896004 | CM3: ='Market Scenario'!AW3 -> 151.79 | CN3: =IFERROR('Market Scenario'!AW3/'Market Scenario'!AW$2-1,"") -> -0.0012501645 | CO3: ='Market Scenario'!AX3 -> 1299075 | CP3: =IFERROR('Market Scenario'!AX3/'Market Scenario'!AX$2-1,"") -> 0.00012317973 | CQ3: ='Market Scenario'!AY3 -> 4222727 | CR3: =IFERROR('Market Scenario'!AY3/'Market Scenario'!AY$2-1,"") -> -0.0011661306 | CS3: ='Market Scenario'!AZ3 -> 33643.85 | CT3: =IFERROR('Market Scenario'!AZ3/'Market Scenario'!AZ$2-1,"") -> 0.0017943287 | CU3: ='Market Scenario'!BA3 -> 679331.8 | CV3: =IFERROR('Market Scenario'!BA3/'Market Scenario'!BA$2-1,"") -> -0.0010303919 | CW3: ='Market Scenario'!BB3 -> 471011.7 | CX3: =IFERROR('Market Scenario'!BB3/'Market Scenario'!BB$2-1,"") -> -0.0019896146 | CY3: ='Market Scenario'!BC3 -> 42187.25 | CZ3: =IFERROR('Market Scenario'!BC3/'Market Scenario'!BC$2-1,"") -> 0.00029045643 | DA3: ='Market Scenario'!BD3 -> 54471.93 | DB3: =IFERROR('Market Scenario'!BD3/'Market Scenario'!BD$2-1,"") -> 0.0013056769
A4: ='Market Scenario'!A4 -> Scenario 2 | B4: ='Market Scenario'!B4 -> 3 | C4: ='Market Scenario'!C4 -> 1 | D4: ='Market Scenario'!D4 -> Fake Positive News | E4: ='Market Scenario'!E4 -> 3 | F4: ='Market Scenario'!F4 -> TRADING | G4: ='Market Scenario'!G4 -> 154590.7 | H4: =IFERROR('Market Scenario'!G4/'Market Scenario'!G$2-1,"") -> 0.0038761301 | I4: ='Market Scenario'!H4 -> 208027.6 | J4: =IFERROR('Market Scenario'!H4/'Market Scenario'!H$2-1,"") -> -0.0047312054 | K4: ='Market Scenario'!I4 -> 161748.2 | L4: =IFERROR('Market Scenario'!I4/'Market Scenario'!I$2-1,"") -> 0.00021210298 | M4: ='Market Scenario'!J4 -> 267506.2 | N4: =IFERROR('Market Scenario'!J4/'Market Scenario'!J$2-1,"") -> 0.0018602334 | O4: ='Market Scenario'!K4 -> 536731.8 | P4: =IFERROR('Market Scenario'!K4/'Market Scenario'!K$2-1,"") -> -0.0042382763 | Q4: ='Market Scenario'!L4 -> 500951.5 | R4: =IFERROR('Market Scenario'!L4/'Market Scenario'!L$2-1,"") -> -0.0020123053 | S4: ='Market Scenario'!M4 -> 232198.2 | T4: =IFERROR('Market Scenario'!M4/'Market Scenario'!M$2-1,"") -> -0.0012980645 | U4: ='Market Scenario'!N4 -> 506562.7 | V4: =IFERROR('Market Scenario'!N4/'Market Scenario'!N$2-1,"") -> -0.0048714989 | W4: ='Market Scenario'!O4 -> 704842.4 | X4: =IFERROR('Market Scenario'!O4/'Market Scenario'!O$2-1,"") -> -0.00030706654 | Y4: ='Market Scenario'!P4 -> 921745.8 | Z4: =IFERROR('Market Scenario'!P4/'Market Scenario'!P$2-1,"") -> 0.0040205665 | AA4: ='Market Scenario'!Q4 -> 467104.2 | AB4: =IFERROR('Market Scenario'!Q4/'Market Scenario'!Q$2-1,"") -> -0.0050323058 | AC4: ='Market Scenario'!R4 -> 293273.2 | AD4: =IFERROR('Market Scenario'!R4/'Market Scenario'!R$2-1,"") -> -0.0025728693 | AE4: ='Market Scenario'!S4 -> 1623047 | AF4: =IFERROR('Market Scenario'!S4/'Market Scenario'!S$2-1,"") -> -0.0036519427 | AG4: ='Market Scenario'!T4 -> 21042.83 | AH4: =IFERROR('Market Scenario'!T4/'Market Scenario'!T$2-1,"") -> -0.0049523444 | AI4: ='Market Scenario'!U4 -> 437403.9 | AJ4: =IFERROR('Market Scenario'!U4/'Market Scenario'!U$2-1,"") -> 0.0015960362 | AK4: ='Market Scenario'!V4 -> 44495.65 | AL4: =IFERROR('Market Scenario'!V4/'Market Scenario'!V$2-1,"") -> 3.1463849e-06 | AM4: ='Market Scenario'!W4 -> 320693 | AN4: =IFERROR('Market Scenario'!W4/'Market Scenario'!W$2-1,"") -> 0.0022411063 | AO4: ='Market Scenario'!X4 -> 475831.8 | AP4: =IFERROR('Market Scenario'!X4/'Market Scenario'!X$2-1,"") -> 0.00076598279 | AQ4: ='Market Scenario'!Y4 -> 1442573 | AR4: =IFERROR('Market Scenario'!Y4/'Market Scenario'!Y$2-1,"") -> -0.0030594333 | AS4: ='Market Scenario'!Z4 -> 47061.94 | AT4: =IFERROR('Market Scenario'!Z4/'Market Scenario'!Z$2-1,"") -> -0.00088103969 | AU4: ='Market Scenario'!AA4 -> 126835.5 | AV4: =IFERROR('Market Scenario'!AA4/'Market Scenario'!AA$2-1,"") -> 0.0019575362 | AW4: ='Market Scenario'!AB4 -> 475294.2 | AX4: =IFERROR('Market Scenario'!AB4/'Market Scenario'!AB$2-1,"") -> 0.00058208357 | AY4: ='Market Scenario'!AC4 -> 377873 | AZ4: =IFERROR('Market Scenario'!AC4/'Market Scenario'!AC$2-1,"") -> -0.00033492099 | BA4: ='Market Scenario'!AD4 -> 428780.7 | BB4: =IFERROR('Market Scenario'!AD4/'Market Scenario'!AD$2-1,"") -> -0.00044734792 | BC4: ='Market Scenario'!AE4 -> 98474 | BD4: =IFERROR('Market Scenario'!AE4/'Market Scenario'!AE$2-1,"") -> 0.0047707069 | BE4: ='Market Scenario'!AF4 -> 120780.8 | BF4: =IFERROR('Market Scenario'!AF4/'Market Scenario'!AF$2-1,"") -> -6.457563e-05 | BG4: ='Market Scenario'!AG4 -> 143866.7 | BH4: =IFERROR('Market Scenario'!AG4/'Market Scenario'!AG$2-1,"") -> 0.0041424356 | BI4: ='Market Scenario'!AH4 -> 189008.3 | BJ4: =IFERROR('Market Scenario'!AH4/'Market Scenario'!AH$2-1,"") -> 0.0033283558 | BK4: ='Market Scenario'!AI4 -> 105273.2 | BL4: =IFERROR('Market Scenario'!AI4/'Market Scenario'!AI$2-1,"") -> -0.00019374397 | BM4: ='Market Scenario'!AJ4 -> 156091.7 | BN4: =IFERROR('Market Scenario'!AJ4/'Market Scenario'!AJ$2-1,"") -> 0.0019185739 | BO4: ='Market Scenario'!AK4 -> 126571.1 | BP4: =IFERROR('Market Scenario'!AK4/'Market Scenario'!AK$2-1,"") -> -0.0002867131 | BQ4: ='Market Scenario'!AL4 -> 130458.1 | BR4: =IFERROR('Market Scenario'!AL4/'Market Scenario'!AL$2-1,"") -> -1.4563851e-05 | BS4: ='Market Scenario'!AM4 -> 145046.9 | BT4: =IFERROR('Market Scenario'!AM4/'Market Scenario'!AM$2-1,"") -> -0.0045699486 | BU4: ='Market Scenario'!AN4 -> 106020.1 | BV4: =IFERROR('Market Scenario'!AN4/'Market Scenario'!AN$2-1,"") -> 0.0023655123 | BW4: ='Market Scenario'!AO4 -> 157691.6 | BX4: =IFERROR('Market Scenario'!AO4/'Market Scenario'!AO$2-1,"") -> -0.00060967958 | BY4: ='Market Scenario'!AP4 -> 127843.4 | BZ4: =IFERROR('Market Scenario'!AP4/'Market Scenario'!AP$2-1,"") -> 0.00041787307 | CA4: ='Market Scenario'!AQ4 -> 113715 | CB4: =IFERROR('Market Scenario'!AQ4/'Market Scenario'!AQ$2-1,"") -> -0.00034811779 | CC4: ='Market Scenario'!AR4 -> 1481903 | CD4: =IFERROR('Market Scenario'!AR4/'Market Scenario'!AR$2-1,"") -> -0.0019705973 | CE4: ='Market Scenario'!AS4 -> 20195.79 | CF4: =IFERROR('Market Scenario'!AS4/'Market Scenario'!AS$2-1,"") -> 0.001014606 | CG4: ='Market Scenario'!AT4 -> 17077.34 | CH4: =IFERROR('Market Scenario'!AT4/'Market Scenario'!AT$2-1,"") -> -0.00045010164 | CI4: ='Market Scenario'!AU4 -> 122304.1 | CJ4: =IFERROR('Market Scenario'!AU4/'Market Scenario'!AU$2-1,"") -> -0.0016130388 | CK4: ='Market Scenario'!AV4 -> 214646.9 | CL4: =IFERROR('Market Scenario'!AV4/'Market Scenario'!AV$2-1,"") -> -0.0041278372 | CM4: ='Market Scenario'!AW4 -> 151.87 | CN4: =IFERROR('Market Scenario'!AW4/'Market Scenario'!AW$2-1,"") -> -0.00072377944 | CO4: ='Market Scenario'!AX4 -> 1298334 | CP4: =IFERROR('Market Scenario'!AX4/'Market Scenario'!AX$2-1,"") -> -0.0004472964 | CQ4: ='Market Scenario'!AY4 -> 4219440 | CR4: =IFERROR('Market Scenario'!AY4/'Market Scenario'!AY$2-1,"") -> -0.0019436298 | CS4: ='Market Scenario'!AZ4 -> 33733.43 | CT4: =IFERROR('Market Scenario'!AZ4/'Market Scenario'!AZ$2-1,"") -> 0.0044617029 | CU4: ='Market Scenario'!BA4 -> 679656.3 | CV4: =IFERROR('Market Scenario'!BA4/'Market Scenario'!BA$2-1,"") -> -0.00055320885 | CW4: ='Market Scenario'!BB4 -> 469769.6 | CX4: =IFERROR('Market Scenario'!BB4/'Market Scenario'!BB$2-1,"") -> -0.0046214573 | CY4: ='Market Scenario'!BC4 -> 42199.3 | CZ4: =IFERROR('Market Scenario'!BC4/'Market Scenario'!BC$2-1,"") -> 0.00057617072 | DA4: ='Market Scenario'!BD4 -> 54533.93 | DB4: =IFERROR('Market Scenario'!BD4/'Market Scenario'!BD$2-1,"") -> 0.002445364
A5: ='Market Scenario'!A5 -> Scenario 2 | B5: ='Market Scenario'!B5 -> 4 | C5: ='Market Scenario'!C5 -> 1 | D5: ='Market Scenario'!D5 -> Fake Positive News | E5: ='Market Scenario'!E5 -> 4 | F5: ='Market Scenario'!F5 -> TRADING | G5: ='Market Scenario'!G5 -> 154987.5 | H5: =IFERROR('Market Scenario'!G5/'Market Scenario'!G$2-1,"") -> 0.0064528572 | I5: ='Market Scenario'!H5 -> 207652.5 | J5: =IFERROR('Market Scenario'!H5/'Market Scenario'!H$2-1,"") -> -0.0065258006 | K5: ='Market Scenario'!I5 -> 161786.1 | L5: =IFERROR('Market Scenario'!I5/'Market Scenario'!I$2-1,"") -> 0.0004464675 | M5: ='Market Scenario'!J5 -> 267624.3 | N5: =IFERROR('Market Scenario'!J5/'Market Scenario'!J$2-1,"") -> 0.0023025398 | O5: ='Market Scenario'!K5 -> 535929.5 | P5: =IFERROR('Market Scenario'!K5/'Market Scenario'!K$2-1,"") -> -0.0057267285 | Q5: ='Market Scenario'!L5 -> 499675.3 | R5: =IFERROR('Market Scenario'!L5/'Market Scenario'!L$2-1,"") -> -0.0045547309 | S5: ='Market Scenario'!M5 -> 232054.4 | T5: =IFERROR('Market Scenario'!M5/'Market Scenario'!M$2-1,"") -> -0.0019165591 | U5: ='Market Scenario'!N5 -> 505229.2 | V5: =IFERROR('Market Scenario'!N5/'Market Scenario'!N$2-1,"") -> -0.007491123 | W5: ='Market Scenario'!O5 -> 704816.1 | X5: =IFERROR('Market Scenario'!O5/'Market Scenario'!O$2-1,"") -> -0.00034436839 | Y5: ='Market Scenario'!P5 -> 923530.1 | Z5: =IFERROR('Market Scenario'!P5/'Market Scenario'!P$2-1,"") -> 0.0059641326 | AA5: ='Market Scenario'!Q5 -> 465933.2 | AB5: =IFERROR('Market Scenario'!Q5/'Market Scenario'!Q$2-1,"") -> -0.0075266254 | AC5: ='Market Scenario'!R5 -> 293235.9 | AD5: =IFERROR('Market Scenario'!R5/'Market Scenario'!R$2-1,"") -> -0.0026997273 | AE5: ='Market Scenario'!S5 -> 1621320 | AF5: =IFERROR('Market Scenario'!S5/'Market Scenario'!S$2-1,"") -> -0.0047121049 | AG5: ='Market Scenario'!T5 -> 21000.12 | AH5: =IFERROR('Market Scenario'!T5/'Market Scenario'!T$2-1,"") -> -0.0069719627 | AI5: ='Market Scenario'!U5 -> 437853.4 | AJ5: =IFERROR('Market Scenario'!U5/'Market Scenario'!U$2-1,"") -> 0.0026253306 | AK5: ='Market Scenario'!V5 -> 44433.93 | AL5: =IFERROR('Market Scenario'!V5/'Market Scenario'!V$2-1,"") -> -0.0013839599 | AM5: ='Market Scenario'!W5 -> 320908.5 | AN5: =IFERROR('Market Scenario'!W5/'Market Scenario'!W$2-1,"") -> 0.0029145945 | AO5: ='Market Scenario'!X5 -> 475912.9 | AP5: =IFERROR('Market Scenario'!X5/'Market Scenario'!X$2-1,"") -> 0.00093655172 | AQ5: ='Market Scenario'!Y5 -> 1439709 | AR5: =IFERROR('Market Scenario'!Y5/'Market Scenario'!Y$2-1,"") -> -0.0050387008 | AS5: ='Market Scenario'!Z5 -> 47057.43 | AT5: =IFERROR('Market Scenario'!Z5/'Market Scenario'!Z$2-1,"") -> -0.00097678641 | AU5: ='Market Scenario'!AA5 -> 126757.8 | AV5: =IFERROR('Market Scenario'!AA5/'Market Scenario'!AA$2-1,"") -> 0.0013437324 | AW5: ='Market Scenario'!AB5 -> 475190.6 | AX5: =IFERROR('Market Scenario'!AB5/'Market Scenario'!AB$2-1,"") -> 0.00036398644 | AY5: ='Market Scenario'!AC5 -> 377866.5 | AZ5: =IFERROR('Market Scenario'!AC5/'Market Scenario'!AC$2-1,"") -> -0.00035211677 | BA5: ='Market Scenario'!AD5 -> 428758.7 | BB5: =IFERROR('Market Scenario'!AD5/'Market Scenario'!AD$2-1,"") -> -0.00049863325 | BC5: ='Market Scenario'!AE5 -> 98720.37 | BD5: =IFERROR('Market Scenario'!AE5/'Market Scenario'!AE$2-1,"") -> 0.0072845213 | BE5: ='Market Scenario'!AF5 -> 120812.6 | BF5: =IFERROR('Market Scenario'!AF5/'Market Scenario'!AF$2-1,"") -> 0.00019869425 | BG5: ='Market Scenario'!AG5 -> 144138 | BH5: =IFERROR('Market Scenario'!AG5/'Market Scenario'!AG$2-1,"") -> 0.0060360207 | BI5: ='Market Scenario'!AH5 -> 189280 | BJ5: =IFERROR('Market Scenario'!AH5/'Market Scenario'!AH$2-1,"") -> 0.0047706434 | BK5: ='Market Scenario'!AI5 -> 105337.6 | BL5: =IFERROR('Market Scenario'!AI5/'Market Scenario'!AI$2-1,"") -> 0.00041787915 | BM5: ='Market Scenario'!AJ5 -> 156325.9 | BN5: =IFERROR('Market Scenario'!AJ5/'Market Scenario'!AJ$2-1,"") -> 0.0034218526 | BO5: ='Market Scenario'!AK5 -> 126479.6 | BP5: =IFERROR('Market Scenario'!AK5/'Market Scenario'!AK$2-1,"") -> -0.0010094197 | BQ5: ='Market Scenario'!AL5 -> 130466.8 | BR5: =IFERROR('Market Scenario'!AL5/'Market Scenario'!AL$2-1,"") -> 5.2123256e-05 | BS5: ='Market Scenario'!AM5 -> 144747.9 | BT5: =IFERROR('Market Scenario'!AM5/'Market Scenario'!AM$2-1,"") -> -0.0066219303 | BU5: ='Market Scenario'!AN5 -> 106051.9 | BV5: =IFERROR('Market Scenario'!AN5/'Market Scenario'!AN$2-1,"") -> 0.0026661649 | BW5: ='Market Scenario'!AO5 -> 157652 | BX5: =IFERROR('Market Scenario'!AO5/'Market Scenario'!AO$2-1,"") -> -0.00086064956 | BY5: ='Market Scenario'!AP5 -> 127833.5 | BZ5: =IFERROR('Market Scenario'!AP5/'Market Scenario'!AP$2-1,"") -> 0.00034040222 | CA5: ='Market Scenario'!AQ5 -> 113744.4 | CB5: =IFERROR('Market Scenario'!AQ5/'Market Scenario'!AQ$2-1,"") -> -8.9666704e-05 | CC5: ='Market Scenario'!AR5 -> 1479954 | CD5: =IFERROR('Market Scenario'!AR5/'Market Scenario'!AR$2-1,"") -> -0.0032832063 | CE5: ='Market Scenario'!AS5 -> 20211.21 | CF5: =IFERROR('Market Scenario'!AS5/'Market Scenario'!AS$2-1,"") -> 0.0017789061 | CG5: ='Market Scenario'!AT5 -> 17053.83 | CH5: =IFERROR('Market Scenario'!AT5/'Market Scenario'!AT$2-1,"") -> -0.0018261601 | CI5: ='Market Scenario'!AU5 -> 122293.4 | CJ5: =IFERROR('Market Scenario'!AU5/'Market Scenario'!AU$2-1,"") -> -0.0017003846 | CK5: ='Market Scenario'!AV5 -> 214320.3 | CL5: =IFERROR('Market Scenario'!AV5/'Market Scenario'!AV$2-1,"") -> -0.0056431251 | CM5: ='Market Scenario'!AW5 -> 151.94 | CN5: =IFERROR('Market Scenario'!AW5/'Market Scenario'!AW$2-1,"") -> -0.00026319253 | CO5: ='Market Scenario'!AX5 -> 1297102 | CP5: =IFERROR('Market Scenario'!AX5/'Market Scenario'!AX$2-1,"") -> -0.0013957803 | CQ5: ='Market Scenario'!AY5 -> 4213606 | CR5: =IFERROR('Market Scenario'!AY5/'Market Scenario'!AY$2-1,"") -> -0.0033235903 | CS5: ='Market Scenario'!AZ5 -> 33803.91 | CT5: =IFERROR('Market Scenario'!AZ5/'Market Scenario'!AZ$2-1,"") -> 0.0065603469 | CU5: ='Market Scenario'!BA5 -> 679177.9 | CV5: =IFERROR('Market Scenario'!BA5/'Market Scenario'!BA$2-1,"") -> -0.0012567046 | CW5: ='Market Scenario'!BB5 -> 468852.2 | CX5: =IFERROR('Market Scenario'!BB5/'Market Scenario'!BB$2-1,"") -> -0.0065653044 | CY5: ='Market Scenario'!BC5 -> 42209.99 | CZ5: =IFERROR('Market Scenario'!BC5/'Market Scenario'!BC$2-1,"") -> 0.00082963841 | DA5: ='Market Scenario'!BD5 -> 54564.59 | DB5: =IFERROR('Market Scenario'!BD5/'Market Scenario'!BD$2-1,"") -> 0.0030089576
A6: ='Market Scenario'!A6 -> Scenario 2 | B6: ='Market Scenario'!B6 -> 5 | C6: ='Market Scenario'!C6 -> 1 | D6: ='Market Scenario'!D6 -> Fake Positive News | E6: ='Market Scenario'!E6 -> 5 | F6: ='Market Scenario'!F6 -> TRADING | G6: ='Market Scenario'!G6 -> 155043.9 | H6: =IFERROR('Market Scenario'!G6/'Market Scenario'!G$2-1,"") -> 0.0068191057 | I6: ='Market Scenario'!H6 -> 207299 | J6: =IFERROR('Market Scenario'!H6/'Market Scenario'!H$2-1,"") -> -0.0082170546 | K6: ='Market Scenario'!I6 -> 161843.4 | L6: =IFERROR('Market Scenario'!I6/'Market Scenario'!I$2-1,"") -> 0.00080079696 | M6: ='Market Scenario'!J6 -> 267527.7 | N6: =IFERROR('Market Scenario'!J6/'Market Scenario'!J$2-1,"") -> 0.0019407549 | O6: ='Market Scenario'!K6 -> 534831.5 | P6: =IFERROR('Market Scenario'!K6/'Market Scenario'!K$2-1,"") -> -0.0077637726 | Q6: ='Market Scenario'!L6 -> 498657.9 | R6: =IFERROR('Market Scenario'!L6/'Market Scenario'!L$2-1,"") -> -0.0065815791 | S6: ='Market Scenario'!M6 -> 231711.5 | T6: =IFERROR('Market Scenario'!M6/'Market Scenario'!M$2-1,"") -> -0.0033913978 | U6: ='Market Scenario'!N6 -> 503825.8 | V6: =IFERROR('Market Scenario'!N6/'Market Scenario'!N$2-1,"") -> -0.010248064 | W6: ='Market Scenario'!O6 -> 704721.2 | X6: =IFERROR('Market Scenario'!O6/'Market Scenario'!O$2-1,"") -> -0.00047896708 | Y6: ='Market Scenario'!P6 -> 926458.5 | Z6: =IFERROR('Market Scenario'!P6/'Market Scenario'!P$2-1,"") -> 0.0091539208 | AA6: ='Market Scenario'!Q6 -> 464584 | AB6: =IFERROR('Market Scenario'!Q6/'Market Scenario'!Q$2-1,"") -> -0.010400525 | AC6: ='Market Scenario'!R6 -> 292865.8 | AD6: =IFERROR('Market Scenario'!R6/'Market Scenario'!R$2-1,"") -> -0.0039584437 | AE6: ='Market Scenario'!S6 -> 1618992 | AF6: =IFERROR('Market Scenario'!S6/'Market Scenario'!S$2-1,"") -> -0.006141206 | AG6: ='Market Scenario'!T6 -> 20942.91 | AH6: =IFERROR('Market Scenario'!T6/'Market Scenario'!T$2-1,"") -> -0.0096772394 | AI6: ='Market Scenario'!U6 -> 438436.7 | AJ6: =IFERROR('Market Scenario'!U6/'Market Scenario'!U$2-1,"") -> 0.0039610091 | AK6: ='Market Scenario'!V6 -> 44391.57 | AL6: =IFERROR('Market Scenario'!V6/'Market Scenario'!V$2-1,"") -> -0.002335966 | AM6: ='Market Scenario'!W6 -> 321350.6 | AN6: =IFERROR('Market Scenario'!W6/'Market Scenario'!W$2-1,"") -> 0.0042962611 | AO6: ='Market Scenario'!X6 -> 475844.3 | AP6: =IFERROR('Market Scenario'!X6/'Market Scenario'!X$2-1,"") -> 0.0007922727 | AQ6: ='Market Scenario'!Y6 -> 1436938 | AR6: =IFERROR('Market Scenario'!Y6/'Market Scenario'!Y$2-1,"") -> -0.0069536973 | AS6: ='Market Scenario'!Z6 -> 47056.68 | AT6: =IFERROR('Market Scenario'!Z6/'Market Scenario'!Z$2-1,"") -> -0.00099270881 | AU6: ='Market Scenario'!AA6 -> 126847.7 | AV6: =IFERROR('Market Scenario'!AA6/'Market Scenario'!AA$2-1,"") -> 0.002053912 | AW6: ='Market Scenario'!AB6 -> 474843.6 | AX6: =IFERROR('Market Scenario'!AB6/'Market Scenario'!AB$2-1,"") -> -0.00036651266 | AY6: ='Market Scenario'!AC6 -> 377951.6 | AZ6: =IFERROR('Market Scenario'!AC6/'Market Scenario'!AC$2-1,"") -> -0.00012698426 | BA6: ='Market Scenario'!AD6 -> 428496.5 | BB6: =IFERROR('Market Scenario'!AD6/'Market Scenario'!AD$2-1,"") -> -0.0011098611 | BC6: ='Market Scenario'!AE6 -> 98831.17 | BD6: =IFERROR('Market Scenario'!AE6/'Market Scenario'!AE$2-1,"") -> 0.0084150593 | BE6: ='Market Scenario'!AF6 -> 120824.8 | BF6: =IFERROR('Market Scenario'!AF6/'Market Scenario'!AF$2-1,"") -> 0.00029969716 | BG6: ='Market Scenario'!AG6 -> 144498.7 | BH6: =IFERROR('Market Scenario'!AG6/'Market Scenario'!AG$2-1,"") -> 0.0085535885 | BI6: ='Market Scenario'!AH6 -> 189484.4 | BJ6: =IFERROR('Market Scenario'!AH6/'Market Scenario'!AH$2-1,"") -> 0.0058556768 | BK6: ='Market Scenario'!AI6 -> 105333.1 | BL6: =IFERROR('Market Scenario'!AI6/'Market Scenario'!AI$2-1,"") -> 0.00037514151 | BM6: ='Market Scenario'!AJ6 -> 156519.7 | BN6: =IFERROR('Market Scenario'!AJ6/'Market Scenario'!AJ$2-1,"") -> 0.0046658125 | BO6: ='Market Scenario'!AK6 -> 126279.6 | BP6: =IFERROR('Market Scenario'!AK6/'Market Scenario'!AK$2-1,"") -> -0.0025891062 | BQ6: ='Market Scenario'!AL6 -> 130472.3 | BR6: =IFERROR('Market Scenario'!AL6/'Market Scenario'!AL$2-1,"") -> 9.4281772e-05 | BS6: ='Market Scenario'!AM6 -> 144465.6 | BT6: =IFERROR('Market Scenario'!AM6/'Market Scenario'!AM$2-1,"") -> -0.008559303 | BU6: ='Market Scenario'!AN6 -> 105946.8 | BV6: =IFERROR('Market Scenario'!AN6/'Market Scenario'!AN$2-1,"") -> 0.0016724985 | BW6: ='Market Scenario'!AO6 -> 157621.3 | BX6: =IFERROR('Market Scenario'!AO6/'Market Scenario'!AO$2-1,"") -> -0.0010552147 | BY6: ='Market Scenario'!AP6 -> 127828.4 | BZ6: =IFERROR('Market Scenario'!AP6/'Market Scenario'!AP$2-1,"") -> 0.000300493 | CA6: ='Market Scenario'!AQ6 -> 113724.7 | CB6: =IFERROR('Market Scenario'!AQ6/'Market Scenario'!AQ$2-1,"") -> -0.00026284651 | CC6: ='Market Scenario'!AR6 -> 1479084 | CD6: =IFERROR('Market Scenario'!AR6/'Market Scenario'!AR$2-1,"") -> -0.0038691324 | CE6: ='Market Scenario'!AS6 -> 20206.76 | CF6: =IFERROR('Market Scenario'!AS6/'Market Scenario'!AS$2-1,"") -> 0.0015583396 | CG6: ='Market Scenario'!AT6 -> 17039.37 | CH6: =IFERROR('Market Scenario'!AT6/'Market Scenario'!AT$2-1,"") -> -0.0026725151 | CI6: ='Market Scenario'!AU6 -> 122146.5 | CJ6: =IFERROR('Market Scenario'!AU6/'Market Scenario'!AU$2-1,"") -> -0.0028995516 | CK6: ='Market Scenario'!AV6 -> 213811.4 | CL6: =IFERROR('Market Scenario'!AV6/'Market Scenario'!AV$2-1,"") -> -0.008004209 | CM6: ='Market Scenario'!AW6 -> 152.13 | CN6: =IFERROR('Market Scenario'!AW6/'Market Scenario'!AW$2-1,"") -> 0.00098697197 | CO6: ='Market Scenario'!AX6 -> 1293458 | CP6: =IFERROR('Market Scenario'!AX6/'Market Scenario'!AX$2-1,"") -> -0.0042011987 | CQ6: ='Market Scenario'!AY6 -> 4211795 | CR6: =IFERROR('Market Scenario'!AY6/'Market Scenario'!AY$2-1,"") -> -0.00375196 | CS6: ='Market Scenario'!AZ6 -> 33871.96 | CT6: =IFERROR('Market Scenario'!AZ6/'Market Scenario'!AZ$2-1,"") -> 0.0085866341 | CU6: ='Market Scenario'!BA6 -> 678866.6 | CV6: =IFERROR('Market Scenario'!BA6/'Market Scenario'!BA$2-1,"") -> -0.0017144769 | CW6: ='Market Scenario'!BB6 -> 468316.8 | CX6: =IFERROR('Market Scenario'!BB6/'Market Scenario'!BB$2-1,"") -> -0.0076997449 | CY6: ='Market Scenario'!BC6 -> 42209.47 | CZ6: =IFERROR('Market Scenario'!BC6/'Market Scenario'!BC$2-1,"") -> 0.00081730883 | DA6: ='Market Scenario'!BD6 -> 54616.51 | DB6: =IFERROR('Market Scenario'!BD6/'Market Scenario'!BD$2-1,"") -> 0.0039633535
A7: ='Market Scenario'!A7 -> Scenario 2 | B7: ='Market Scenario'!B7 -> 6 | C7: ='Market Scenario'!C7 -> 1 | D7: ='Market Scenario'!D7 -> Fake Positive News | E7: ='Market Scenario'!E7 -> 6 | F7: ='Market Scenario'!F7 -> TRADING | G7: ='Market Scenario'!G7 -> 155419.6 | H7: =IFERROR('Market Scenario'!G7/'Market Scenario'!G$2-1,"") -> 0.0092588143 | I7: ='Market Scenario'!H7 -> 206847.2 | J7: =IFERROR('Market Scenario'!H7/'Market Scenario'!H$2-1,"") -> -0.010378606 | K7: ='Market Scenario'!I7 -> 161858.2 | L7: =IFERROR('Market Scenario'!I7/'Market Scenario'!I$2-1,"") -> 0.00089231662 | M7: ='Market Scenario'!J7 -> 267724.5 | N7: =IFERROR('Market Scenario'!J7/'Market Scenario'!J$2-1,"") -> 0.0026778073 | O7: ='Market Scenario'!K7 -> 533669.4 | P7: =IFERROR('Market Scenario'!K7/'Market Scenario'!K$2-1,"") -> -0.0099197371 | Q7: ='Market Scenario'!L7 -> 497906.1 | R7: =IFERROR('Market Scenario'!L7/'Market Scenario'!L$2-1,"") -> -0.0080793033 | S7: ='Market Scenario'!M7 -> 231474.6 | T7: =IFERROR('Market Scenario'!M7/'Market Scenario'!M$2-1,"") -> -0.0044103226 | U7: ='Market Scenario'!N7 -> 502275.8 | V7: =IFERROR('Market Scenario'!N7/'Market Scenario'!N$2-1,"") -> -0.013292996 | W7: ='Market Scenario'!O7 -> 705022.6 | X7: =IFERROR('Market Scenario'!O7/'Market Scenario'!O$2-1,"") -> -5.148506e-05 | Y7: ='Market Scenario'!P7 -> 929435 | Z7: =IFERROR('Market Scenario'!P7/'Market Scenario'!P$2-1,"") -> 0.012396102 | AA7: ='Market Scenario'!Q7 -> 463316.3 | AB7: =IFERROR('Market Scenario'!Q7/'Market Scenario'!Q$2-1,"") -> -0.013100823 | AC7: ='Market Scenario'!R7 -> 292825.5 | AD7: =IFERROR('Market Scenario'!R7/'Market Scenario'!R$2-1,"") -> -0.0040955046 | AE7: ='Market Scenario'!S7 -> 1614799 | AF7: =IFERROR('Market Scenario'!S7/'Market Scenario'!S$2-1,"") -> -0.0087151841 | AG7: ='Market Scenario'!T7 -> 20894.15 | AH7: =IFERROR('Market Scenario'!T7/'Market Scenario'!T$2-1,"") -> -0.011982943 | AI7: ='Market Scenario'!U7 -> 439061 | AJ7: =IFERROR('Market Scenario'!U7/'Market Scenario'!U$2-1,"") -> 0.005390572 | AK7: ='Market Scenario'!V7 -> 44394.39 | AL7: =IFERROR('Market Scenario'!V7/'Market Scenario'!V$2-1,"") -> -0.0022725889 | AM7: ='Market Scenario'!W7 -> 321909.2 | AN7: =IFERROR('Market Scenario'!W7/'Market Scenario'!W$2-1,"") -> 0.0060420175 | AO7: ='Market Scenario'!X7 -> 475992.3 | AP7: =IFERROR('Market Scenario'!X7/'Market Scenario'!X$2-1,"") -> 0.0011035452 | AQ7: ='Market Scenario'!Y7 -> 1434924 | AR7: =IFERROR('Market Scenario'!Y7/'Market Scenario'!Y$2-1,"") -> -0.0083455425 | AS7: ='Market Scenario'!Z7 -> 47045.98 | AT7: =IFERROR('Market Scenario'!Z7/'Market Scenario'!Z$2-1,"") -> -0.0012198684 | AU7: ='Market Scenario'!AA7 -> 126870.9 | AV7: =IFERROR('Market Scenario'!AA7/'Market Scenario'!AA$2-1,"") -> 0.0022371842 | AW7: ='Market Scenario'!AB7 -> 474551.8 | AX7: =IFERROR('Market Scenario'!AB7/'Market Scenario'!AB$2-1,"") -> -0.00098080556 | AY7: ='Market Scenario'!AC7 -> 377881.2 | AZ7: =IFERROR('Market Scenario'!AC7/'Market Scenario'!AC$2-1,"") -> -0.00031322784 | BA7: ='Market Scenario'!AD7 -> 428240.6 | BB7: =IFERROR('Market Scenario'!AD7/'Market Scenario'!AD$2-1,"") -> -0.0017064027 | BC7: ='Market Scenario'!AE7 -> 99015.68 | BD7: =IFERROR('Market Scenario'!AE7/'Market Scenario'!AE$2-1,"") -> 0.010297691 | BE7: ='Market Scenario'!AF7 -> 120803.2 | BF7: =IFERROR('Market Scenario'!AF7/'Market Scenario'!AF$2-1,"") -> 0.00012087233 | BG7: ='Market Scenario'!AG7 -> 144825.8 | BH7: =IFERROR('Market Scenario'!AG7/'Market Scenario'!AG$2-1,"") -> 0.010836639 | BI7: ='Market Scenario'!AH7 -> 189960.9 | BJ7: =IFERROR('Market Scenario'!AH7/'Market Scenario'!AH$2-1,"") -> 0.008385121 | BK7: ='Market Scenario'!AI7 -> 105345.5 | BL7: =IFERROR('Market Scenario'!AI7/'Market Scenario'!AI$2-1,"") -> 0.00049290745 | BM7: ='Market Scenario'!AJ7 -> 156740.1 | BN7: =IFERROR('Market Scenario'!AJ7/'Market Scenario'!AJ$2-1,"") -> 0.0060805121 | BO7: ='Market Scenario'!AK7 -> 126246.1 | BP7: =IFERROR('Market Scenario'!AK7/'Market Scenario'!AK$2-1,"") -> -0.0028537037 | BQ7: ='Market Scenario'!AL7 -> 130490 | BR7: =IFERROR('Market Scenario'!AL7/'Market Scenario'!AL$2-1,"") -> 0.00022995554 | BS7: ='Market Scenario'!AM7 -> 144205.7 | BT7: =IFERROR('Market Scenario'!AM7/'Market Scenario'!AM$2-1,"") -> -0.010342949 | BU7: ='Market Scenario'!AN7 -> 106127.9 | BV7: =IFERROR('Market Scenario'!AN7/'Market Scenario'!AN$2-1,"") -> 0.0033847059 | BW7: ='Market Scenario'!AO7 -> 157685.8 | BX7: =IFERROR('Market Scenario'!AO7/'Market Scenario'!AO$2-1,"") -> -0.00064643781 | BY7: ='Market Scenario'!AP7 -> 127814.6 | BZ7: =IFERROR('Market Scenario'!AP7/'Market Scenario'!AP$2-1,"") -> 0.00019250333 | CA7: ='Market Scenario'!AQ7 -> 113679.8 | CB7: =IFERROR('Market Scenario'!AQ7/'Market Scenario'!AQ$2-1,"") -> -0.00065755583 | CC7: ='Market Scenario'!AR7 -> 1479227 | CD7: =IFERROR('Market Scenario'!AR7/'Market Scenario'!AR$2-1,"") -> -0.003772825 | CE7: ='Market Scenario'!AS7 -> 20198.38 | CF7: =IFERROR('Market Scenario'!AS7/'Market Scenario'!AS$2-1,"") -> 0.0011429806 | CG7: ='Market Scenario'!AT7 -> 17014.47 | CH7: =IFERROR('Market Scenario'!AT7/'Market Scenario'!AT$2-1,"") -> -0.0041299313 | CI7: ='Market Scenario'!AU7 -> 122115.8 | CJ7: =IFERROR('Market Scenario'!AU7/'Market Scenario'!AU$2-1,"") -> -0.0031501604 | CK7: ='Market Scenario'!AV7 -> 213349.7 | CL7: =IFERROR('Market Scenario'!AV7/'Market Scenario'!AV$2-1,"") -> -0.010146305 | CM7: ='Market Scenario'!AW7 -> 152.33 | CN7: =IFERROR('Market Scenario'!AW7/'Market Scenario'!AW$2-1,"") -> 0.0023029346 | CO7: ='Market Scenario'!AX7 -> 1291950 | CP7: =IFERROR('Market Scenario'!AX7/'Market Scenario'!AX$2-1,"") -> -0.0053621677 | CQ7: ='Market Scenario'!AY7 -> 4206536 | CR7: =IFERROR('Market Scenario'!AY7/'Market Scenario'!AY$2-1,"") -> -0.0049959114 | CS7: ='Market Scenario'!AZ7 -> 33948.4 | CT7: =IFERROR('Market Scenario'!AZ7/'Market Scenario'!AZ$2-1,"") -> 0.010862746 | CU7: ='Market Scenario'!BA7 -> 678640.5 | CV7: =IFERROR('Market Scenario'!BA7/'Market Scenario'!BA$2-1,"") -> -0.002046961 | CW7: ='Market Scenario'!BB7 -> 467508.9 | CX7: =IFERROR('Market Scenario'!BB7/'Market Scenario'!BB$2-1,"") -> -0.0094115763 | CY7: ='Market Scenario'!BC7 -> 42204.72 | CZ7: =IFERROR('Market Scenario'!BC7/'Market Scenario'!BC$2-1,"") -> 0.00070468287 | DA7: ='Market Scenario'!BD7 -> 54630.25 | DB7: =IFERROR('Market Scenario'!BD7/'Market Scenario'!BD$2-1,"") -> 0.0042159229
A8: ='Market Scenario'!A8 -> Scenario 2 | B8: ='Market Scenario'!B8 -> 7 | C8: ='Market Scenario'!C8 -> 1 | D8: ='Market Scenario'!D8 -> Fake Positive News | E8: ='Market Scenario'!E8 -> 7 | F8: ='Market Scenario'!F8 -> TRADING | G8: ='Market Scenario'!G8 -> 155753 | H8: =IFERROR('Market Scenario'!G8/'Market Scenario'!G$2-1,"") -> 0.011423837 | I8: ='Market Scenario'!H8 -> 206385.1 | J8: =IFERROR('Market Scenario'!H8/'Market Scenario'!H$2-1,"") -> -0.012589437 | K8: ='Market Scenario'!I8 -> 161879.8 | L8: =IFERROR('Market Scenario'!I8/'Market Scenario'!I$2-1,"") -> 0.0010258858 | M8: ='Market Scenario'!J8 -> 267966.8 | N8: =IFERROR('Market Scenario'!J8/'Market Scenario'!J$2-1,"") -> 0.0035852657 | O8: ='Market Scenario'!K8 -> 532377.7 | P8: =IFERROR('Market Scenario'!K8/'Market Scenario'!K$2-1,"") -> -0.01231614 | Q8: ='Market Scenario'!L8 -> 497054.4 | R8: =IFERROR('Market Scenario'!L8/'Market Scenario'!L$2-1,"") -> -0.0097760466 | S8: ='Market Scenario'!M8 -> 231145.2 | T8: =IFERROR('Market Scenario'!M8/'Market Scenario'!M$2-1,"") -> -0.0058270968 | U8: ='Market Scenario'!N8 -> 500742.5 | V8: =IFERROR('Market Scenario'!N8/'Market Scenario'!N$2-1,"") -> -0.016305122 | W8: ='Market Scenario'!O8 -> 705080.7 | X8: =IFERROR('Market Scenario'!O8/'Market Scenario'!O$2-1,"") -> 3.0919403e-05 | Y8: ='Market Scenario'!P8 -> 932335.4 | Z8: =IFERROR('Market Scenario'!P8/'Market Scenario'!P$2-1,"") -> 0.015555391 | AA8: ='Market Scenario'!Q8 -> 462079.5 | AB8: =IFERROR('Market Scenario'!Q8/'Market Scenario'!Q$2-1,"") -> -0.015735301 | AC8: ='Market Scenario'!R8 -> 292717 | AD8: =IFERROR('Market Scenario'!R8/'Market Scenario'!R$2-1,"") -> -0.004464515 | AE8: ='Market Scenario'!S8 -> 1612451 | AF8: =IFERROR('Market Scenario'!S8/'Market Scenario'!S$2-1,"") -> -0.010156563 | AG8: ='Market Scenario'!T8 -> 20845.85 | AH8: =IFERROR('Market Scenario'!T8/'Market Scenario'!T$2-1,"") -> -0.014266894 | AI8: ='Market Scenario'!U8 -> 439682.6 | AJ8: =IFERROR('Market Scenario'!U8/'Market Scenario'!U$2-1,"") -> 0.0068139523 | AK8: ='Market Scenario'!V8 -> 44361.89 | AL8: =IFERROR('Market Scenario'!V8/'Market Scenario'!V$2-1,"") -> -0.0030029996 | AM8: ='Market Scenario'!W8 -> 322313.1 | AN8: =IFERROR('Market Scenario'!W8/'Market Scenario'!W$2-1,"") -> 0.0073043001 | AO8: ='Market Scenario'!X8 -> 476260.3 | AP8: =IFERROR('Market Scenario'!X8/'Market Scenario'!X$2-1,"") -> 0.0016672009 | AQ8: ='Market Scenario'!Y8 -> 1433236 | AR8: =IFERROR('Market Scenario'!Y8/'Market Scenario'!Y$2-1,"") -> -0.009512094 | AS8: ='Market Scenario'!Z8 -> 47047.67 | AT8: =IFERROR('Market Scenario'!Z8/'Market Scenario'!Z$2-1,"") -> -0.00118399 | AU8: ='Market Scenario'!AA8 -> 126800.9 | AV8: =IFERROR('Market Scenario'!AA8/'Market Scenario'!AA$2-1,"") -> 0.0016842079 | AW8: ='Market Scenario'!AB8 -> 474461.8 | AX8: =IFERROR('Market Scenario'!AB8/'Market Scenario'!AB$2-1,"") -> -0.0011702722 | AY8: ='Market Scenario'!AC8 -> 377949.1 | AZ8: =IFERROR('Market Scenario'!AC8/'Market Scenario'!AC$2-1,"") -> -0.00013359802 | BA8: ='Market Scenario'!AD8 -> 428184.8 | BB8: =IFERROR('Market Scenario'!AD8/'Market Scenario'!AD$2-1,"") -> -0.0018364809 | BC8: ='Market Scenario'!AE8 -> 99336.81 | BD8: =IFERROR('Market Scenario'!AE8/'Market Scenario'!AE$2-1,"") -> 0.013574312 | BE8: ='Market Scenario'!AF8 -> 120778.8 | BF8: =IFERROR('Market Scenario'!AF8/'Market Scenario'!AF$2-1,"") -> -8.1133484e-05 | BG8: ='Market Scenario'!AG8 -> 145202.5 | BH8: =IFERROR('Market Scenario'!AG8/'Market Scenario'!AG$2-1,"") -> 0.013465882 | BI8: ='Market Scenario'!AH8 -> 190116.1 | BJ8: =IFERROR('Market Scenario'!AH8/'Market Scenario'!AH$2-1,"") -> 0.009208982 | BK8: ='Market Scenario'!AI8 -> 105344.7 | BL8: =IFERROR('Market Scenario'!AI8/'Market Scenario'!AI$2-1,"") -> 0.00048530965 | BM8: ='Market Scenario'!AJ8 -> 157011.7 | BN8: =IFERROR('Market Scenario'!AJ8/'Market Scenario'!AJ$2-1,"") -> 0.0078238532 | BO8: ='Market Scenario'!AK8 -> 126078.3 | BP8: =IFERROR('Market Scenario'!AK8/'Market Scenario'!AK$2-1,"") -> -0.0041790606 | BQ8: ='Market Scenario'!AL8 -> 130477.8 | BR8: =IFERROR('Market Scenario'!AL8/'Market Scenario'!AL$2-1,"") -> 0.00013644029 | BS8: ='Market Scenario'!AM8 -> 143982.2 | BT8: =IFERROR('Market Scenario'!AM8/'Market Scenario'!AM$2-1,"") -> -0.011876788 | BU8: ='Market Scenario'!AN8 -> 106220.5 | BV8: =IFERROR('Market Scenario'!AN8/'Market Scenario'!AN$2-1,"") -> 0.0042601912 | BW8: ='Market Scenario'!AO8 -> 157614.5 | BX8: =IFERROR('Market Scenario'!AO8/'Market Scenario'!AO$2-1,"") -> -0.0010983105 | BY8: ='Market Scenario'!AP8 -> 127786.5 | BZ8: =IFERROR('Market Scenario'!AP8/'Market Scenario'!AP$2-1,"") -> -2.7388685e-05 | CA8: ='Market Scenario'!AQ8 -> 113694.8 | CB8: =IFERROR('Market Scenario'!AQ8/'Market Scenario'!AQ$2-1,"") -> -0.00052569303 | CC8: ='Market Scenario'!AR8 -> 1478673 | CD8: =IFERROR('Market Scenario'!AR8/'Market Scenario'!AR$2-1,"") -> -0.004145932 | CE8: ='Market Scenario'!AS8 -> 20188.06 | CF8: =IFERROR('Market Scenario'!AS8/'Market Scenario'!AS$2-1,"") -> 0.00063146458 | CG8: ='Market Scenario'!AT8 -> 16997.95 | CH8: =IFERROR('Market Scenario'!AT8/'Market Scenario'!AT$2-1,"") -> -0.0050968596 | CI8: ='Market Scenario'!AU8 -> 122059.2 | CJ8: =IFERROR('Market Scenario'!AU8/'Market Scenario'!AU$2-1,"") -> -0.0036121948 | CK8: ='Market Scenario'!AV8 -> 212823.6 | CL8: =IFERROR('Market Scenario'!AV8/'Market Scenario'!AV$2-1,"") -> -0.012587189 | CM8: ='Market Scenario'!AW8 -> 152.43 | CN8: =IFERROR('Market Scenario'!AW8/'Market Scenario'!AW$2-1,"") -> 0.0029609159 | CO8: ='Market Scenario'!AX8 -> 1291310 | CP8: =IFERROR('Market Scenario'!AX8/'Market Scenario'!AX$2-1,"") -> -0.0058548866 | CQ8: ='Market Scenario'!AY8 -> 4204625 | CR8: =IFERROR('Market Scenario'!AY8/'Market Scenario'!AY$2-1,"") -> -0.0054479349 | CS8: ='Market Scenario'!AZ8 -> 34025.81 | CT8: =IFERROR('Market Scenario'!AZ8/'Market Scenario'!AZ$2-1,"") -> 0.013167741 | CU8: ='Market Scenario'!BA8 -> 678880.4 | CV8: =IFERROR('Market Scenario'!BA8/'Market Scenario'!BA$2-1,"") -> -0.0016941837 | CW8: ='Market Scenario'!BB8 -> 466533.5 | CX8: =IFERROR('Market Scenario'!BB8/'Market Scenario'!BB$2-1,"") -> -0.011478318 | CY8: ='Market Scenario'!BC8 -> 42202.33 | CZ8: =IFERROR('Market Scenario'!BC8/'Market Scenario'!BC$2-1,"") -> 0.00064801423 | DA8: ='Market Scenario'!BD8 -> 54735.29 | DB8: =IFERROR('Market Scenario'!BD8/'Market Scenario'!BD$2-1,"") -> 0.0061467733
